Workbook

Sheet Intro
A1: English | B1: Italiano | M1: # giorni anno -2 | N1: 365
A2: Current module tests do not run just regression tests but also functional tests. | B2: Gli attuali test dei moduli non eseguono solo test di regressione ma anche test funzionali. | M2: # giorni anno -1 | N2: 365
A3: This worksheet contains the workflow of the current module functional tests with test data and expected values. | B3: Questo foglio di lavoro contiene il flusso di lavoro dei test funzionali del modulo corrente con i dati dei test e i valori attesi. | M3: # giorni anno 0 | N3: 365
A4: Look at the tabbeds for furthermore info about tests. | B4: Consulta le schede per ulteriori informazioni sui test.
A10: Specific notes for this module | B10: Note specifiche per questo modulo
A11: The tests are based on 4 goods: | B11: I test si basano su 4 beni:
A12: - 2 have 50% depreciation in 1st year (#1 & #3) | B12: - 2 hanno un ammortamento del 50% nel 1° anno (#1 e #3)
A13: - 2 have pro-rata-temporis depreciation on 1st year (#2 & #4) | B13: - 2 hanno ammortamento pro-rata-temporis al 1° anno (#2 e #4)
A14: - 1 with fixed asset write-down (#3) | B14: - 1 con svalutazione del bene (#3)
A15: - 1 is partial dismissed (#4) | B15: - 1 è dismesso parzialmente (#4)

Sheet Completo #1
A1: Descrizione | B1: Valore | C1: Residuo | E1: Note
A2: Valore iniziale | B2: 1000 | C2: =B2 -> 1000 | F2: % amm | G2: 0.25
A3: # giorni anno-2 | B3: 183 | E3: Compreso giorno di acquisto | F3: Q.A. | G3: =$B$2*G2 -> 250
A4: QA anno-2 | B4: =$G$3/2 -> 125 | C4: =C2-B4 -> 875 | E4: Quota per 50% anno | F4: %dism | G4: 1
A5: QA anno-1 | B5: =$G$3 -> 250 | C5: =C4-B5 -> 625 | E5: Quota intero anno
A6: # giorni anno | B6: 31 | E6: Compreso giorno di vendita
A7: QA anno | B7: =$G$3*B6/365 -> 21.232877 | C7: =C5-B7 -> 603.76712 | E7: Quota alla data di vendita
A8: Dismissione totale | B8: =C7*$G$4 -> 603.76712 | C8: =C7-B8 -> 0 | E8: Residuo
A9: Prezzo vendita | B9: 1400 | E9: Da fattura di vendita
A10: Plusvalenza | B10: =B9-B8 -> 796.23288 | E10: Plusvalenza perché venduto > dismissione
A13: Registrazioni contabili | B13: Dare | C13: Avere | F13: Dare | G13: Avere | H13: Saldo | I13: Da calcolo bene
E14: Fornitore | G14: =$B$2 -> 1000 | H14: =F14-G14 -> -1000
A15: Ammortamento anno-2 | E15: Bene | F15: =$B$2 -> 1000 | H15: =F15-G15 -> 1000
A16: Fondo | C16: =B4 -> 125 | E16: Fondo | G16: =C16 -> 125 | H16: =F16-G16 -> -125
A17: QA | B17: =B4 -> 125 | E17: QA | F17: =B17 -> 125 | H17: =F17-G17 -> 125
A18: controllo | B18: =SUM(B15:B17) -> 125 | C18: =SUM(C15:C17) -> 125 | E18: Valore residuo del bene | H18: =H15+H16 -> 875 | I18: =C4 -> 875
A20: Ammortamento anno-1 | E20: Bene | F20: =$B$2 -> 1000 | H20: =F20-G20 -> 1000
A21: Fondo | C21: =B5 -> 250 | E21: Fondo | G21: =G16+C21 -> 375 | H21: =F21-G21 -> -375
A22: QA | B22: =B5 -> 250 | E22: QA | F22: =B22 -> 250 | H22: =F22-G22 -> 250
A23: controllo | B23: =SUM(B20:B22) -> 250 | C23: =SUM(C20:C22) -> 250 | E23: Valore residuo del bene | H23: =H20+H21 -> 625 | I23: =C5 -> 625
A25: Ammortamento anno | E25: Bene | F25: =$B$2 -> 1000 | H25: =F25-G25 -> 1000
A26: Fondo | C26: =B7 -> 21.232877 | E26: Fondo | G26: =G21+C26 -> 396.23288 | H26: =F26-G26 -> -396.23288
A27: QA | B27: =B7 -> 21.232877 | E27: QA | F27: =B27 -> 21.232877 | H27: =F27-G27 -> 21.232877
A28: controllo | B28: =SUM(B25:B27) -> 21.232877 | C28: =SUM(C25:C27) -> 21.232877 | E28: Valore residuo del bene | H28: =H25+H26 -> 603.76712 | I28: =C7 -> 603.76712
A30: Fattura di dismissione | E30: Bene | F30: =$B$2 -> 1000 | G30: =C32 -> 1400 | H30: =F30-G30 -> -400
A31: Cliente | B31: =B9 -> 1400 | E31: Fondo | G31: =G26 -> 396.23288 | H31: =F31-G31 -> -396.23288
A32: Bene | C32: =B9 -> 1400 | E32: QA | F32: =B32 -> 0 | H32: =F32-G32 -> 0
A33: controllo | B33: =SUM(B30:B32) -> 1400 | C33: =SUM(C30:C32) -> 1400 | E33: Valore residuo del bene | H33: =H30+H31 -> -796.23288
A35: Dismissione totale | E35: Bene | F35: =F30+B36 -> 1400 | G35: =G30+C39 -> 1400 | H35: =F35-G35 -> 0
A36: Bene | B36: =B10-G26 -> 400 | E36: Fondo | F36: =F26+B38 -> 396.23288 | G36: =G26 -> 396.23288 | H36: =F36-G36 -> 0
A37: Plusvalenza | C37: =B10 -> 796.23288 | E37: QA | F37: =B37 -> 0 | H37: =F37-G37 -> 0
A38: Fondo | B38: =G26 -> 396.23288 | E38: Plusvalenza | G38: =C37 -> 796.23288 | H38: =F38-G38 -> -796.23288
A39: Bene | C39: 0 | E39: Valore residuo del bene | H39: =H35+H36 -> 0 | I39: =C8 -> 0
A40: controllo | B40: =SUM(B35:B39) -> 796.23288 | C40: =SUM(C35:C39) -> 796.23288
A42: Dismissione senza fattura
A43: Bene | C43: =C32-B36 -> 1000 | E43: Bene | F43: =F25 -> 1000 | G43: =G25+C43 -> 1000 | H43: =F43-G43 -> 0
A44: Plusvalenza | C44: =C37 -> 796.23288 | E44: Fondo | F44: =F26+B45 -> 396.23288 | G44: =G26 -> 396.23288 | H44: =F44-G44 -> 0
A45: Fondo | B45: =B38 -> 396.23288 | E45: QA | F45: 0 | H45: =F45-G45 -> 0
A46: Transitorio | B46: =B9 -> 1400
A47: controllo | B47: =SUM(B42:B46) -> 1796.2329 | C47: =SUM(C42:C46) -> 1796.2329 | E47: Plusvalenza | G47: =C44 -> 796.23288 | H47: =F47-G47 -> -796.23288
...

Sheet Completo #2
A1: Descrizione | B1: Valore | C1: Residuo | E1: Note
A2: Valore iniziale | B2: 2500 | C2: =B2 -> 2500 | F2: % amm | G2: 0.24
A3: # giorni anno-2 | B3: 92 | E3: 50% dei giorni | F3: Q.A. | G3: =$B$2*G2 -> 600
A4: QA anno-2 | B4: =$G$3*B3/Intro!$N$1 -> 151.23288 | C4: =C2-B4 -> 2348.7671 | E4: Quota per 50% anno | F4: %dism | G4: 1
A5: QA anno-1 | B5: =$G$3 -> 600 | C5: =C4-B5 -> 1748.7671 | E5: Quota intero anno
A6: # giorni anno | B6: 31 | E6: Compreso giorno di vendita
A7: QA anno | B7: =$G$3*B6/365 -> 50.958904 | C7: =C5-B7 -> 1697.8082 | E7: Quota alla data di vendita
A8: Dismissione totale | B8: =C7*$G$4 -> 1697.8082 | C8: =C7-B8 -> 0 | E8: Residuo
A9: Prezzo vendita | B9: 3210 | E9: Da fattura di vendita
A10: Plusvalenza | B10: =B9-B8 -> 1512.1918 | E10: Plusvalenza perché venduto > dismissione
A13: Registrazioni contabili | B13: Dare | C13: Avere | F13: Dare | G13: Avere | H13: Saldo | I13: Da calcolo bene
E14: Fornitore | G14: =$B$2 -> 2500 | H14: =F14-G14 -> -2500
A15: Ammortamento 2020 | E15: Bene | F15: =$B$2 -> 2500 | H15: =F15-G15 -> 2500
A16: Fondo | C16: =B4 -> 151.23288 | E16: Fondo | G16: =C16 -> 151.23288 | H16: =F16-G16 -> -151.23288
A17: QA | B17: =B4 -> 151.23288 | E17: QA | F17: =B17 -> 151.23288 | H17: =F17-G17 -> 151.23288
A18: controllo | B18: =SUM(B15:B17) -> 151.23288 | C18: =SUM(C15:C17) -> 151.23288 | E18: Valore residuo del bene | H18: =H15+H16 -> 2348.7671 | I18: =C4 -> 2348.7671
A20: Ammortamento 2021 | E20: Bene | F20: =$B$2 -> 2500 | H20: =F20-G20 -> 2500
A21: Fondo | C21: =B5 -> 600 | E21: Fondo | G21: =G16+C21 -> 751.23288 | H21: =F21-G21 -> -751.23288
A22: QA | B22: =B5 -> 600 | E22: QA | F22: =B22 -> 600 | H22: =F22-G22 -> 600
A23: controllo | B23: =SUM(B20:B22) -> 600 | C23: =SUM(C20:C22) -> 600 | E23: Valore residuo del bene | H23: =H20+H21 -> 1748.7671 | I23: =C5 -> 1748.7671
A25: Ammortamento 2022 | E25: Bene | F25: =$B$2 -> 2500 | H25: =F25-G25 -> 2500
A26: Fondo | C26: =B7 -> 50.958904 | E26: Fondo | G26: =G21+C26 -> 802.19178 | H26: =F26-G26 -> -802.19178
A27: QA | B27: =B7 -> 50.958904 | E27: QA | F27: =B27 -> 50.958904 | H27: =F27-G27 -> 50.958904
A28: controllo | B28: =SUM(B25:B27) -> 50.958904 | C28: =SUM(C25:C27) -> 50.958904 | E28: Valore residuo del bene | H28: =H25+H26 -> 1697.8082 | I28: =C7 -> 1697.8082
A30: Fattura di dismissione | E30: Bene | F30: =$B$2 -> 2500 | G30: =C32 -> 3210 | H30: =F30-G30 -> -710
A31: Cliente | B31: =B9 -> 3210 | E31: Fondo | G31: =G26 -> 802.19178 | H31: =F31-G31 -> -802.19178
A32: Bene | C32: =B9 -> 3210 | E32: QA | F32: =B32 -> 0 | H32: =F32-G32 -> 0
A33: controllo | B33: =SUM(B30:B32) -> 3210 | C33: =SUM(C30:C32) -> 3210 | E33: Valore residuo del bene | H33: =H30+H31 -> -1512.1918
A35: Dismissione totale | E35: Bene | F35: =F30+B36 -> 3210 | G35: =G30+C39 -> 3210 | H35: =F35-G35 -> 0
A36: Bene | B36: =B10-G26 -> 710 | E36: Fondo | F36: =F26+B38 -> 802.19178 | G36: =G26 -> 802.19178 | H36: =F36-G36 -> 0
A37: Plusvalenza | C37: =B10 -> 1512.1918 | E37: QA | F37: =B37 -> 0 | H37: =F37-G37 -> 0
A38: Fondo | B38: =G26 -> 802.19178 | E38: Plusvalenza | G38: =C37 -> 1512.1918 | H38: =F38-G38 -> -1512.1918
A39: Bene | C39: 0 | E39: Valore residuo del bene | H39: =H35+H36 -> 0 | I39: =C8 -> 0
A40: controllo | B40: =SUM(B35:B39) -> 1512.1918 | C40: =SUM(C35:C39) -> 1512.1918
A43: Dismissione senza fattura
A44: Bene | C44: =C32-B36 -> 2500 | E44: Bene | F44: =F25 -> 2500 | G44: =G25+C44 -> 2500 | H44: =F44-G44 -> 0
A45: Plusvalenza | C45: =C37 -> 1512.1918 | E45: Fondo | F45: =F26+B46 -> 802.19178 | G45: =G26 -> 802.19178 | H45: =F45-G45 -> 0
A46: Fondo | B46: =B38 -> 802.19178 | E46: QA | F46: 0 | H46: =F46-G46 -> 0
A47: Transitorio | B47: =B9 -> 3210
A48: controllo | B48: =SUM(B43:B47) -> 4012.1918 | C48: =SUM(C43:C47) -> 4012.1918 | E48: Plusvalenza | G48: =C45 -> 1512.1918 | H48: =F48-G48 -> -1512.1918
...

Sheet Svalutazione #3
A1: Descrizione | B1: Valore | C1: Residuo | D1: Valore bene | E1: Note
A2: Valore iniziale | B2: 1000 | C2: =B2 -> 1000 | D2: =B2 -> 1000 | F2: % amm | G2: 0.25
A3: # giorni 2020 | B3: 183 | E3: 50% dei giorni | F3: Q.A. | G3: =$B$2*G2 -> 250
A4: QA 2020 | B4: =G3/2 -> 125 | C4: =C2-B4 -> 875 | E4: Quota per 50% anno | F4: %dism | G4: 1
A5: # giorni 2021 | B5: 90
A6: QA 2021 | B6: =$G$3*B5/365 -> 61.643836 | C6: =C4-B6 -> 813.35616 | E6: Quota 90 giorni
A7: Svalutazione | B7: 725 | C7: =C6-B7 -> 88.356164 | D7: =D2-B7 -> 275 | F7: Q.A. dopo svalutaz, | G7: =D7*G2 -> 68.75
A8: # giorni residui 2021 | B8: =365-B5 -> 275
A9: QA 2021 residua | B9: =$G$7*B8/365 -> 51.797945 | C9: =C7-B9 -> 36.558219 | E9: Quota 275 giorni
A10: # giorni 2022 | B10: 31 | E10: Compreso giorno di vendita
A11: QA 2022 | B11: =$G$7*B10/365 -> 5.8390411 | C11: =C9-B11 -> 30.719178 | E11: Quota alla data di vendita
A12: Dismissione totale | B12: =C11*$G$4 -> 30.719178 | C12: =C11-B12 -> 0 | E12: Residuo
A13: Prezzo vendita | B13: 1400 | E13: Da fattura di vendita
A14: Plusvalenza | B14: =B13-B12 -> 1369.2808 | E14: Plusvalenza perché venduto > dismissione
A17: Registrazioni contabili | B17: Dare | C17: Avere | F17: Dare | G17: Avere | H17: Saldo | I17: Da calcolo bene
E18: Fornitore | G18: =$B$2 -> 1000 | H18: =F18-G18 -> -1000
A19: Ammortamento 2020 | E19: Bene | F19: =$B$2 -> 1000 | H19: =F19-G19 -> 1000
A20: Fondo | C20: =B4 -> 125 | E20: Fondo | G20: =C20 -> 125 | H20: =F20-G20 -> -125
A21: QA | B21: =B4 -> 125 | E21: QA | F21: =B21 -> 125 | H21: =F21-G21 -> 125
A22: controllo | B22: =SUM(B19:B21) -> 125 | C22: =SUM(C19:C21) -> 125 | E22: Valore residuo del bene | H22: =H19+H20 -> 875 | I22: =C4 -> 875
A24: Ammortamento 2021 | E24: Bene | F24: =F19 -> 1000 | H24: =F24-G24 -> 1000
A25: Fondo | C25: =B6 -> 61.643836 | E25: Fondo | G25: =G20+C25 -> 186.64384 | H25: =F25-G25 -> -186.64384
A26: QA | B26: =B6 -> 61.643836 | E26: QA | F26: =B26 -> 61.643836 | H26: =F26-G26 -> 61.643836
A27: controllo | B27: =SUM(B24:B26) -> 61.643836 | C27: =SUM(C24:C26) -> 61.643836 | E27: Valore residuo del bene | H27: =H24+H25 -> 813.35616 | I27: =C6 -> 813.35616
A29: Svalutazione | E29: Bene | F29: =F24 -> 1000 | G29: =C30 -> 725 | H29: =F29-G29 -> 275
A30: Bene | C30: =B7 -> 725 | E30: Fondo | G30: =G25 -> 186.64384 | H30: =F30-G30 -> -186.64384
A31: Minusvalenza | B31: =B7 -> 725 | E31: QA | F31: =F26 -> 61.643836 | H31: =F31-G31 -> 61.643836
A32: controllo | B32: =SUM(B29:B31) -> 725 | C32: =SUM(C29:C31) -> 725 | E32: Valore residuo del bene | H32: =H29+H30 -> 88.356164 | I32: =C7 -> 88.356164
A34: Ammortamento 2021 residuo | E34: Bene | F34: =F29 -> 1000 | G34: =G29 -> 725 | H34: =F34-G34 -> 275
A35: Fondo | C35: =B9 -> 51.797945 | E35: Fondo | G35: =G30+C35 -> 238.44178 | H35: =F35-G35 -> -238.44178
A36: QA | B36: =B9 -> 51.797945 | E36: QA | F36: =F31+B36 -> 113.44178 | H36: =F36-G36 -> 113.44178
A37: controllo | B37: =SUM(B34:B36) -> 51.797945 | C37: =SUM(C34:C36) -> 51.797945 | E37: Valore residuo del bene | H37: =H34+H35 -> 36.558219 | I37: =C9 -> 36.558219

Sheet Parziale #4
A1: Descrizione | B1: Valore | C1: Residuo | E1: Note
A2: Valore iniziale | B2: 2500 | C2: =B2 -> 2500 | F2: % amm | G2: 0.24
A3: # giorni anno-2 | B3: 92 | E3: Compreso giorno di acquisto | F3: Q.A. | G3: =$B$2*G2 -> 600
A4: QA anno-2 | B4: =$G$3*B3/Intro!$N$1 -> 151.23288 | C4: =C2-B4 -> 2348.7671 | E4: Quota per 92 giorni | F4: %dism | G4: 0.2
A5: QA anno-1 | B5: =$G$3 -> 600 | C5: =C4-B5 -> 1748.7671 | E5: Quota intero anno
A6: # giorni anno | B6: 212 | E6: Compreso giorno di vendita
A7: QA anno | B7: =$G$3*B6/365 -> 348.49315 | C7: =C5-B7 -> 1400.274 | E7: Quota alla data di vendita
A8: Dismissione parziale 20% | B8: =C7*$G$4 -> 280.05479 | C8: =C7-B8 -> 1120.2192 | E8: Residuo
A9: Prezzo vendita | B9: 550 | E9: Da fattura di vendita
A10: Plusvalenza | B10: =B9-B8 -> 269.94521 | E10: Plusvalenza perché venduto > dismissione
A13: Registrazioni contabili | B13: Dare | C13: Avere | F13: Dare | G13: Avere | H13: Saldo
E14: Fornitore | G14: =$B$2 -> 2500 | H14: =F14-G14 -> -2500
A15: Ammortamento anno-2 | E15: Bene | F15: =$B$2 -> 2500 | H15: =F15-G15 -> 2500
A16: Fondo | C16: =B4 -> 151.23288 | E16: Fondo | G16: =C16 -> 151.23288 | H16: =F16-G16 -> -151.23288
A17: QA | B17: =B4 -> 151.23288 | E17: QA | F17: =B17 -> 151.23288 | H17: =F17-G17 -> 151.23288
A18: controllo | B18: =SUM(B15:B17) -> 151.23288 | C18: =SUM(C15:C17) -> 151.23288 | E18: Valore residuo del bene | H18: =H15+H16 -> 2348.7671
A20: Ammortamento anno-1 | E20: Bene | F20: =$B$2 -> 2500 | H20: =F20-G20 -> 2500
A21: Fondo | C21: =B5 -> 600 | E21: Fondo | G21: =G16+C21 -> 751.23288 | H21: =F21-G21 -> -751.23288
A22: QA | B22: =B5 -> 600 | E22: QA | F22: =B22 -> 600 | H22: =F22-G22 -> 600
A23: controllo | B23: =SUM(B20:B22) -> 600 | C23: =SUM(C20:C22) -> 600 | E23: Valore residuo del bene | H23: =H20+H21 -> 1748.7671
A25: Ammortamento anno | E25: Bene | F25: =$B$2 -> 2500 | H25: =F25-G25 -> 2500
A26: Fondo | C26: =B7 -> 348.49315 | E26: Fondo | G26: =G21+C26 -> 1099.726 | H26: =F26-G26 -> -1099.726
A27: QA | B27: =B7 -> 348.49315 | E27: QA | F27: =B27 -> 348.49315 | H27: =F27-G27 -> 348.49315
A28: controllo | B28: =SUM(B25:B27) -> 348.49315 | C28: =SUM(C25:C27) -> 348.49315 | E28: Valore residuo del bene | H28: =H25+H26 -> 1400.274
A30: Fattura di dismissione | E30: Bene | F30: =$B$2 -> 2500 | G30: =C32 -> 550 | H30: =F30-G30 -> 1950
A31: Cliente | B31: =B9 -> 550 | E31: Fondo | G31: =G26 -> 1099.726 | H31: =F31-G31 -> -1099.726
A32: Bene | C32: =B9 -> 550 | E32: QA | F32: =B32 -> 0 | H32: =F32-G32 -> 0
A33: controllo | B33: =SUM(B30:B32) -> 550 | C33: =SUM(C30:C32) -> 550 | E33: Valore residuo del bene | H33: =H30+H31 -> 850.27397
A35: Dismissione totale | E35: Bene | F35: =F30+B36 -> 2550 | G35: =G30+C39 -> 550 | H35: =F35-G35 -> 2000
A36: Bene | B36: =B10-G26*G4 -> 50 | E36: Fondo | F36: =F26+B38 -> 219.94521 | G36: =G26 -> 1099.726 | H36: =F36-G36 -> -879.78082
A37: Plusvalenza | C37: =B10 -> 269.94521 | E37: QA | F37: =B37 -> 0 | H37: =F37-G37 -> 0
A38: Fondo | B38: =G26*G4 -> 219.94521 | E38: Plusvalenza | G38: =C37 -> 269.94521 | H38: =F38-G38 -> -269.94521
A39: Bene | C39: 0 | E39: Valore residuo del bene | H39: =H35+H36 -> 1120.2192
A40: controllo | B40: =SUM(B35:B39) -> 269.94521 | C40: =SUM(C35:C39) -> 269.94521
A42: Dismissione senza fattura
A43: Bene | C43: =C32-B36 -> 500 | E43: Bene | F43: =F25 -> 2500 | G43: =G25+C43 -> 500 | H43: =F43-G43 -> 2000
A44: Plusvalenza | C44: =C37 -> 269.94521 | E44: Fondo | F44: =F26+B45 -> 219.94521 | G44: =G26 -> 1099.726 | H44: =F44-G44 -> -879.78082
A45: Fondo | B45: =B38 -> 219.94521 | E45: QA | F45: 0 | H45: =F45-G45 -> 0
A46: Transitorio | B46: =B9 -> 550
A47: controllo | B47: =SUM(B42:B46) -> 769.94521 | C47: =SUM(C42:C46) -> 769.94521 | E47: Plusvalenza | G47: =C44 -> 269.94521 | H47: =F47-G47 -> -269.94521
...

Sheet TestbedValues
A1: asset_1.initial_amount | B1: 100.0
A2: asset_1.purchase_amount | B2: ='Completo #1'!$B$2 -> 1000
A3: asset_1.depreciation_amount[1] | B3: ='Completo #1'!$B$4 -> 125
A4: asset_1.depreciated_amount[-1] | B4: =B3 -> 125
A7: asset_2.initial_amount | B7: 250
A8: asset_2.purchase_amount | B8: ='Completo #2'!$B$2 -> 2500
A9: asset_2.depreciation_amount[1] | B9: ='Completo #2'!$B$4 -> 151.23288
A10: asset_2.depreciated_amount[-1] | B10: =B9 -> 151.23288
A13: asset_3.initial_amount | B13: 100.0
A14: asset_3.purchase_amount | B14: ='Svalutazione #3'!$B$2 -> 1000
A15: asset_3.depreciation_amount[1] | B15: ='Svalutazione #3'!$B$4 -> 125
A16: asset_3.depreciated_amount[-1] | B16: =B15 -> 125
A19: asset_4.initial_amount | B19: 100.0
A20: asset_4.purchase_amount | B20: ='Parziale #4'!$B$2 -> 2500
A21: asset_4.depreciation_amount[1] | B21: ='Parziale #4'!$B$4 -> 151.23288
A22: asset_4.depreciated_amount[-1] | B22: =B21 -> 151.23288
